Workbook

Sheet COVER
A1: Bubble and Bee Case
A2: Scenario Analysis
A4: Ellen Burnes

Sheet Summary
B1: 2017
B2: NI | C2: SE | D2: TIE Ratio | E2: Net Cash Inc | F2: ROE | G2: #Pay "misses"
A3: Baseline | B3: ='PF Baseline'!P18 -> 440360.01 | C3: ='PF Baseline'!H30 -> 831521.75 | D3: ='PF Baseline'!P14/'PF Baseline'!P15 -> 348.29354 | E3: ='PF Baseline'!P39 -> 307223.35 | F3: =B3/C3 -> 0.52958327 | G3: 0
A4: Rent No D Growth | B4: ='PF Rent_No Growth'!P19 -> -701.6575 | C4: ='PF Rent_No Growth'!H30 -> 283154.21 | D4: ='PF Rent_No Growth'!P14/'PF Rent_No Growth'!P15 -> -2107.9268 | E4: ='PF Rent_No Growth'!P40 -> -72383.693 | F4: =B4/C4 -> -0.0024780049 | G4: 2
A5: Rent Rev Growth | B5: ='PF Rent Growth'!P19 -> 389403.87 | C5: ='PF Rent Growth'!H30 -> 685117.91 | E5: ='PF Rent Growth'!P40 -> 298484.03 | F5: =B5/C5 -> 0.56837496 | G5: 0
A6: Purchase No D Growth | B6: ='PF Purchase_No Growth'!P18 -> -8799.6575 | C6: ='PF Purchase_No Growth'!H30 -> 429219.21 | D6: ='PF Purchase_No Growth'!P14/'PF Purchase_No Growth'!P15 -> 0.81047883 | E6: ='PF Purchase_No Growth'!P39 -> 98176.307 | F6: =B6/C6 -> -0.020501546 | G6: 3
A7: Purchase Rev Growth | B7: ='PF Purchase Growth'!P18 -> 381305.87 | C7: ='PF Purchase Growth'!H30 -> 831182.91 | D7: ='PF Purchase Growth'!P14/'PF Purchase Growth'!P15 -> 9.2123122 | E7: ='PF Purchase Growth'!P39 -> 294044.03 | F7: =B7/C7 -> 0.45875085 | G7: 1
A8: CCorp Purchase Rev Growth | B8: ='PF Purchase_CCorp'!P19 -> 154729.4 | C8: ='PF Purchase_CCorp'!H30 -> 560224.19 | D8: ='PF Purchase_CCorp'!P15/'PF Purchase_CCorp'!P16 -> 5.4432786 | E8: ='PF Purchase_CCorp'!P40 -> 242467.56 | F8: =B8/C8 -> 0.27619193 | G8: NA
B10: 2015 | C10: 2016 | D10: 2017
A11: Base
A12: CCC | B12: =(365/('PF Baseline'!N6/'PF Baseline'!F9))+(365/('PF Baseline'!N5/'PF Baseline'!F8))-(365/('PF Baseline'!N6/'PF Baseline'!F20)) -> 80.3 | C12: =(365/('PF Baseline'!O6/'PF Baseline'!G9))+(365/('PF Baseline'!O5/'PF Baseline'!G8))-(365/('PF Baseline'!O6/'PF Baseline'!G20)) -> 76.82381 | D12: =(365/('PF Baseline'!P6/'PF Baseline'!H9))+(365/('PF Baseline'!P5/'PF Baseline'!H8))-(365/('PF Baseline'!P6/'PF Baseline'!H20)) -> 76.82381
A13: % Gross Profit | B13: ='PF Baseline'!N7/'PF Baseline'!N5 -> 0.8 | C13: ='PF Baseline'!O7/'PF Baseline'!O5 -> 0.79 | D13: ='PF Baseline'!P7/'PF Baseline'!P5 -> 0.79
A14: % Operating Profit | B14: ='PF Baseline'!N14/'PF Baseline'!N5 -> 0.14848538 | C14: ='PF Baseline'!O14/'PF Baseline'!O5 -> 0.14879446 | D14: ='PF Baseline'!P14/'PF Baseline'!P5 -> 0.1634854
A15: % Net Profit | B15: ='PF Baseline'!N18/'PF Baseline'!N5 -> 0.14577234 | C15: ='PF Baseline'!O18/'PF Baseline'!O5 -> 0.14732401 | D15: ='PF Baseline'!P18/'PF Baseline'!P5 -> 0.16301601
A16: Rev/Assets | B16: ='PF Baseline'!N5/'PF Baseline'!F16 -> 3.4377332 | C16: ='PF Baseline'!O5/'PF Baseline'!G16 -> 3.1947417 | D16: ='PF Baseline'!P5/'PF Baseline'!H16 -> 2.7777086
A17: ROA | B17: ='PF Baseline'!N18/'PF Baseline'!F16 -> 0.50112641 | C17: ='PF Baseline'!O18/'PF Baseline'!G16 -> 0.47066217 | D17: ='PF Baseline'!P18/'PF Baseline'!H16 -> 0.45281098
A18: ROE | B18: ='PF Baseline'!N18/'PF Baseline'!F32 -> 0.50112641 | C18: ='PF Baseline'!O18/'PF Baseline'!G32 -> 0.47066243 | D18: ='PF Baseline'!P18/'PF Baseline'!H32 -> 0.45281113
A20: Rent No Growth
A21: CCC | B21: =(365/('PF Rent_No Growth'!N6/'PF Rent_No Growth'!F9))+(365/('PF Rent_No Growth'!N5/'PF Rent_No Growth'!F8))-(365/('PF Rent_No Growth'!N6/'PF Rent_No Growth'!F20)) -> 80.3 | C21: =(365/('PF Rent_No Growth'!O6/'PF Rent_No Growth'!G9))+(365/('PF Rent_No Growth'!O5/'PF Rent_No Growth'!G8))-(365/('PF Rent_No Growth'!O6/'PF Rent_No Growth'!G20)) -> 76.82381 | D21: =(365/('PF Rent_No Growth'!P6/'PF Rent_No Growth'!H9))+(365/('PF Rent_No Growth'!P5/'PF Rent_No Growth'!H8))-(365/('PF Rent_No Growth'!P6/'PF Rent_No Growth'!H20)) -> 76.82381
A22: % Gross Profit | B22: ='PF Rent_No Growth'!N7/'PF Rent_No Growth'!N5 -> 0.8 | C22: ='PF Rent_No Growth'!O7/'PF Rent_No Growth'!O5 -> 0.79 | D22: ='PF Rent_No Growth'!P7/'PF Rent_No Growth'!P5 -> 0.79
A23: % Operating Profit | B23: ='PF Rent_No Growth'!N15/'PF Rent_No Growth'!N5 -> 0.073965299 | C23: ='PF Rent_No Growth'!O15/'PF Rent_No Growth'!O5 -> 0.028694948 | D23: ='PF Rent_No Growth'!P15/'PF Rent_No Growth'!P5 -> -0.00037495369
A24: % Net Profit | B24: ='PF Rent_No Growth'!N19/'PF Rent_No Growth'!N5 -> 0.073965299 | C24: ='PF Rent_No Growth'!O19/'PF Rent_No Growth'!O5 -> 0.028694948 | D24: ='PF Rent_No Growth'!P19/'PF Rent_No Growth'!P5 -> -0.00037495369
A25: Rev/Assets | B25: ='PF Rent_No Growth'!N5/'PF Rent_No Growth'!F16 -> 3.7791469 | C25: ='PF Rent_No Growth'!O5/'PF Rent_No Growth'!G16 -> 3.4550389 | D25: ='PF Rent_No Growth'!P5/'PF Rent_No Growth'!H16 -> 5.2270436
A26: ROA | B26: ='PF Rent_No Growth'!N19/'PF Rent_No Growth'!F16 -> 0.27952573 | C26: ='PF Rent_No Growth'!O19/'PF Rent_No Growth'!G16 -> 0.099142159 | D26: ='PF Rent_No Growth'!P19/'PF Rent_No Growth'!H16 -> -0.0019598993
A27: ROE | B27: ='PF Rent_No Growth'!N19/'PF Rent_No Growth'!F30 -> 0.32930548 | C27: ='PF Rent_No Growth'!O19/'PF Rent_No Growth'!G30 -> 0.11504101 | D27: ='PF Rent_No Growth'!P19/'PF Rent_No Growth'!H30 -> -0.0024780049
A29: Rent with Growth
A30: CCC | B30: =(365/('PF Rent Growth'!N6/'PF Rent Growth'!F9))+(365/('PF Rent Growth'!N5/'PF Rent Growth'!F8))-(365/('PF Rent Growth'!N6/'PF Rent Growth'!F20)) -> 80.3 | C30: =(365/('PF Rent Growth'!O6/'PF Rent Growth'!G9))+(365/('PF Rent Growth'!O5/'PF Rent Growth'!G8))-(365/('PF Rent Growth'!O6/'PF Rent Growth'!G20)) -> 76.82381 | D30: =(365/('PF Rent Growth'!P6/'PF Rent Growth'!H9))+(365/('PF Rent Growth'!P5/'PF Rent Growth'!H8))-(365/('PF Rent Growth'!P6/'PF Rent Growth'!H20)) -> 76.82381
A31: % Gross Profit | B31: ='PF Rent Growth'!N7/'PF Rent Growth'!N5 -> 0.8 | C31: ='PF Rent Growth'!O7/'PF Rent Growth'!O5 -> 0.79 | D31: ='PF Rent Growth'!P7/'PF Rent Growth'!P5 -> 0.79
A32: % Operating Profit | B32: ='PF Rent Growth'!N15/'PF Rent Growth'!N5 -> 0.12292002 | C32: ='PF Rent Growth'!O15/'PF Rent Growth'!O5 -> 0.12656139 | D32: ='PF Rent Growth'!P15/'PF Rent Growth'!P5 -> 0.14415267
A33: % Net Profit | B33: ='PF Rent Growth'!N19/'PF Rent Growth'!N5 -> 0.12292002 | C33: ='PF Rent Growth'!O19/'PF Rent Growth'!O5 -> 0.12656139 | D33: ='PF Rent Growth'!P19/'PF Rent Growth'!P5 -> 0.14415267
A34: Rev/Assets | B34: ='PF Rent Growth'!N5/'PF Rent Growth'!F16 -> 4.7488106 | C34: ='PF Rent Growth'!O5/'PF Rent Growth'!G16 -> 4.1598957 | D34: ='PF Rent Growth'!P5/'PF Rent Growth'!H16 -> 3.4057337
A35: ROA | B35: ='PF Rent Growth'!N19/'PF Rent Growth'!F16 -> 0.5837239 | C35: ='PF Rent Growth'!O19/'PF Rent Growth'!G16 -> 0.52648218 | D35: ='PF Rent Growth'!P19/'PF Rent Growth'!H16 -> 0.49094561
A36: ROE | B36: ='PF Rent Growth'!N19/'PF Rent Growth'!F30 -> 0.72060446 | C36: ='PF Rent Growth'!O19/'PF Rent Growth'!G30 -> 0.63157335 | D36: ='PF Rent Growth'!P19/'PF Rent Growth'!H30 -> 0.56837496
A38: Buy No Growth
A39: CCC | B39: =(365/('PF Purchase_No Growth'!N6/'PF Purchase_No Growth'!F9))+(365/('PF Purchase_No Growth'!N5/'PF Purchase_No Growth'!F8))-(365/('PF Purchase_No Growth'!N6/'PF Purchase_No Growth'!F20)) -> 80.3 | C39: =(365/('PF Purchase_No Growth'!O6/'PF Purchase_No Growth'!G9))+(365/('PF Purchase_No Growth'!O5/'PF Purchase_No Growth'!G8))-(365/('PF Purchase_No Growth'!O6/'PF Purchase_No Growth'!G20)) -> 76.82381 | D39: =(365/('PF Purchase_No Growth'!P6/'PF Purchase_No Growth'!H9))+(365/('PF Purchase_No Growth'!P5/'PF Purchase_No Growth'!H8))-(365/('PF Purchase_No Growth'!P6/'PF Purchase_No Growth'!H20)) -> 76.82381
A40: % Gross Profit | B40: ='PF Purchase_No Growth'!N7/'PF Purchase_No Growth'!N5 -> 0.8 | C40: ='PF Purchase_No Growth'!O7/'PF Purchase_No Growth'!O5 -> 0.79 | D40: ='PF Purchase_No Growth'!P7/'PF Purchase_No Growth'!P5 -> 0.79
A41: % Operating Profit | B41: ='PF Purchase_No Growth'!N14/'PF Purchase_No Growth'!N5 -> 0.095168549 | C41: ='PF Purchase_No Growth'!O14/'PF Purchase_No Growth'!O5 -> 0.049532624 | D41: ='PF Purchase_No Growth'!P14/'PF Purchase_No Growth'!P5 -> 0.020109542
A42: % Net Profit | B42: ='PF Purchase_No Growth'!N18/'PF Purchase_No Growth'!N5 -> 0.067788462 | C42: ='PF Purchase_No Growth'!O18/'PF Purchase_No Growth'!O5 -> 0.023438372 | D42: ='PF Purchase_No Growth'!P18/'PF Purchase_No Growth'!P5 -> -0.0047023855
A43: Rev/Assets | B43: ='PF Purchase_No Growth'!N5/'PF Purchase_No Growth'!F16 -> 1.266666 | C43: ='PF Purchase_No Growth'!O5/'PF Purchase_No Growth'!G16 -> 1.2773 | D43: ='PF Purchase_No Growth'!P5/'PF Purchase_No Growth'!H16 -> 1.3369555
A44: ROA | B44: ='PF Purchase_No Growth'!N18/'PF Purchase_No Growth'!F16 -> 0.085865343 | C44: ='PF Purchase_No Growth'!O18/'PF Purchase_No Growth'!G16 -> 0.029937832 | D44: ='PF Purchase_No Growth'!P18/'PF Purchase_No Growth'!H16 -> -0.0062868801
...

Sheet PF Baseline
A1: Bubble and Bee Organic - Pro Forma Modeling Template | S1: Assumptions | T1: Income Statement | AA1: buy
S2: g(d) | T2: 0.15 | V2: 2015 | W2: 2016 | X2: 2017 | AA2: rent
A3: Balance Sheet | J3: Income Statement | U3: demand | V3: 143339 | W3: 161999 | X3: 183141
D4: 2013 | E4: 2014 | F4: 2015 | G4: 2016 | H4: 2017 | M4: 2014 | N4: 2015 | O4: 2016 | P4: 2017 | U4: avg price | V4: 14.25 | W4: 14.5 | X4: 14.75
A5: Assets | K5: Revenues | M5: 1776168 | N5: =V5 -> 2042580.8 | O5: =W5 -> 2348985.5 | P5: =X5 -> 2701329.8 | U5: Revenue | V5: =V3*V4 -> 2042580.8 | W5: =W3*W4 -> 2348985.5 | X5: =X3*X4 -> 2701329.8
B6: Current Assets | L6: Cost of Goods Sold | M6: 357597 | N6: =N5*V7 -> 408516.15 | O6: =O5*W7 -> 493286.95 | P6: =P5*X7 -> 567279.25
C7: Cash | D7: 25567 | E7: 43008 | F7: =E7+N39 -> 222384.93 | G7: =F7+O39 -> 338066.62 | H7: =G7+P39 -> 645289.97 | L7: Gross Margin | M7: =M5-M6 -> 1418571 | N7: =N5-N6 -> 1634064.6 | O7: =O5-O6 -> 1855698.5 | P7: =P5-P6 -> 2134050.5 | U7: COGS | V7: 0.2 | W7: 0.21 | X7: 0.21
C8: Receivables | D8: 32375 | E8: 35525 | F8: =N5*$V$23 -> 40851.615 | G8: =O5*$V$23 -> 46979.71 | H8: =P5*$V$23 -> 54026.595 | K8: Expenses | U8: OPEX
C9: Inventories | D9: 131250 | E9: 143937 | F9: =N5*$V$24 -> 163406.46 | G9: =O5*$V$24 -> 187918.84 | H9: =P5*$V$24 -> 216106.38 | L9: Selling | M9: 439512 | N9: =V9*N5 -> 510645.19 | O9: =W9*O5 -> 610736.23 | P9: =X9*P5 -> 729359.03 | U9: sales | V9: 0.25 | W9: 0.26 | X9: 0.27
C10: Total Current Assets | D10: =SUM(D7:D9) -> 189192 | E10: =SUM(E7:E9) -> 222470 | F10: =SUM(F7:F9) -> 426643.01 | G10: =SUM(G7:G9) -> 572965.17 | H10: =SUM(H7:H9) -> 915422.94 | L10: General & Administrative Variable | M10: 82514 | N10: =V10*N5 -> 102129.04 | O10: =W10*O5 -> 117449.28 | P10: =X10*P5 -> 135066.49 | U10: rev dep | V10: 0.05 | W10: 0.05 | X10: 0.05
B11: Fixed Assets | L11: General & Administrative Fixed | M11: 572776 | N11: =M11+V11 -> 622776 | O11: =N11+W11 -> 672776 | P11: =O11+X11 -> 722776 | U11: sg&A (annual inc) | V11: 50000 | W11: 50000 | X11: 50000
C12: PP&E | D12: 395785 | E12: 470185 | F12: =E12-N31 -> 470185 | G12: =F12-O31 -> 570185 | H12: =G12-P31 -> 570185 | L12: Depreciation | M12: 87221 | N12: =V14 -> 95221 | O12: =W14 -> 105221 | P12: =X14 -> 105221 | U12: rent | V12: 675000 | W12: 725000 | X12: 775000
C13: Less Depreciation | D13: 120221 | E13: 207442 | F13: =E13+N12 -> 302663 | G13: =F13+O12 -> 407884 | H13: =G13+P12 -> 513105 | L13: Total Expenses | M13: =SUM(M9:M12) -> 1182023 | N13: =SUM(N9:N12) -> 1330771.2 | O13: =SUM(O9:O12) -> 1506182.5 | P13: =SUM(P9:P12) -> 1692422.5
C14: Total Fixed Assets | D14: =D12-D13 -> 275564 | E14: =E12-E13 -> 262743 | F14: =F12-F13 -> 167522 | G14: =G12-G13 -> 162301 | H14: =H12-H13 -> 57080 | K14: EBIT | M14: =M7-M13 -> 236548 | N14: =N7-N13 -> 303293.38 | O14: =O7-O13 -> 349516.04 | P14: =P7-P13 -> 441627.98 | Q14: =Q7-Q13 -> 0 | U14: Depr Base | V14: 95221 | W14: 105221 | X14: 105221
L15: Net Interest Expense | M15: 7535 | N15: =V50 -> 5541.598 | O15: =W50 -> 3454.0716 | P15: =X50 -> 1267.9764 | Q15: =Y50 -> 0 | U15: Bldg Buy | V15: 36667 | W15: 36667 | X15: 36667
B16: Total Assets | D16: =D10+D14 -> 464756 | E16: =E10+E14 -> 485213 | F16: =F10+F14 -> 594165.01 | G16: =G10+G14 -> 735266.17 | H16: =H10+H14 -> 972502.94 | K16: Taxable Income | M16: =M14-M15 -> 229013 | N16: =N14-N15 -> 297751.78 | O16: =O14-O15 -> 346061.97 | P16: =P14-P15 -> 440360.01
L17: Taxes | M17: 0 | N17: 0 | O17: 0 | P17: 0 | U17: Interest (bldg) | V17: 49500 | W17: 48003 | X17: 46431
A18: Liabilities & Shareholder's Equity | K18: Net Income | M18: =M16-M17 -> 229013 | N18: =N16-N17 -> 297751.78 | O18: =O16-O17 -> 346061.97 | P18: =P16-P17 -> 440360.01 | Q18: =Q16-Q17 -> 0
B19: Current Liabilities | J19: Cash Flow Statement
C20: Accounts Payable | D20: 44625 | E20: 53286 | F20: =N5*$V$31 -> 81703.23 | G20: =O5*$V$31 -> 93959.42 | H20: =P5*$V$31 -> 108053.19
C21: Accrued Liabilities | D21: 0 | E21: 0 | F21: =E21 -> 0 | G21: =F21 -> 0 | H21: =G21 -> 0 | K21: Cash Provided (used) by Operations | U21: Balance Sheets
C22: Bank Loan | D22: 201796 | E22: 159579 | F22: =V48 -> 117362 | G22: =W48+1993 -> 75144.598 | H22: =X48+6074 -> 32927.67 | K22: Net Income | M22: =M18 -> 229013 | N22: =N18 -> 297751.78 | O22: =O18 -> 346061.97 | P22: =P18 -> 440360.01 | V22: % sales
C23: Total Current Liabilities | D23: =SUM(D20:D22) -> 246421 | E23: =SUM(E20:E22) -> 212865 | F23: =SUM(F20:F22) -> 199065.23 | G23: =SUM(G20:G22) -> 169104.02 | H23: =SUM(H20:H22) -> 140980.86 | K23: Plus Depreciation | M23: =M12 -> 87221 | N23: =N12 -> 95221 | O23: =O12 -> 105221 | P23: =P12 -> 105221 | U23: A/R | V23: 0.02
B24: Long Term Liabilities | D24: 0 | E24: 0 | F24: 0 | G24: 0 | H24: 0 | K24: Change in Working Capital | U24: inv | V24: 0.08
C25: Total Liabilities | D25: =D23+D24 -> 246421 | E25: =E23+E24 -> 212865 | F25: =F23+F24 -> 199065.23 | G25: =G23+G24 -> 169104.02 | H25: =H23+H24 -> 140980.86 | L25: Decrease (increase) in Receivables | M25: =D8-E8 -> -3150 | N25: =-(F8-E8) -> -5326.615 | O25: =-(G8-F8) -> -6128.095 | P25: =-(H8-G8) -> -7046.885
L26: Decrease (increase) in Inventory | M26: =D9-E9 -> -12687 | N26: =-(F9-E9) -> -19469.46 | O26: =-(G9-F9) -> -24512.38 | P26: =-(H9-G9) -> -28187.54
B27: Shareholder's Equity | L27: Increase (decrease) in Accts. Payable | M27: =E20-D20 -> 8661 | N27: =F20-E20 -> 28417.23 | O27: =G20-F20 -> 12256.19 | P27: =H20-G20 -> 14093.77 | W27: 2015
C28: Member's Equity | D28: 150000 | E28: 150000 | F28: 150000 | G28: 150000 | H28: 150000 | L28: Increase (decrease) in Accrued Liabilities | M28: =E21-D21 -> 0 | N28: =M28 -> 0 | O28: =N28 -> 0 | P28: =O28 -> 0 | U28: PPE | W28: 100000
C29: Retained Earnings | D29: 68335 | E29: 122348 | F29: =E29+(N18+N37) -> 245099.78 | G29: =F29+(O18+O37) -> 416161.75 | H29: =G29+(P18+P37) -> 681521.75 | L29: Cash Provided (used) by Operations | M29: =M22+M23+M25+M26+M27+M28 -> 309058 | N29: =N22+N23+N25+N26+N27+N28 -> 396593.93 | O29: =O22+O23+O25+O26+O27+O28 -> 432898.68 | P29: =P22+P23+P25+P26+P27+P28 -> 524440.35
C30: Total Shareholder's Equity | D30: =SUM(D28:D29) -> 218335 | E30: =SUM(E28:E29) -> 272348 | F30: =SUM(F28:F29) -> 395099.78 | G30: =SUM(G28:G29) -> 566161.75 | H30: =SUM(H28:H29) -> 831521.75 | K30: Cash Provided (used) by Investments | V30: 2015 | W30: 2016 | X30: 2017
K31: Additions to PP&E | M31: =D12-E12 -> -74400 | N31: 0 | O31: -100000 | P31: 0 | U31: A/P | V31: 0.04
B32: Total Liabilities and Shareholder's Equity | D32: =D25+D30 -> 464756 | E32: =E25+E30 -> 485213 | F32: =F25+F30 -> 594165.01 | G32: =G25+G30 -> 735265.76 | H32: =H25+H30 -> 972502.61 | K32: Other Investments | M32: 0 | U32: current liabilities | V32: 600000 | W32: 600000 | X32: 600000
L33: Cash Provided (used) by Investments | M33: =SUM(M31:M32) -> -74400 | N33: =SUM(N31:N32) -> 0 | O33: =SUM(O31:O32) -> -100000 | P33: =SUM(P31:P32) -> 0
K34: Cash Provided (used) by Financing Activities | U34: LTL
A35: Assumptions | E35: 2014 | F35: 2015 | G35: 2016 | H35: 2017 | L35: Additions (reductions) to Debt | M35: =E22-D22 -> -42217 | N35: =M35 -> -42217 | O35: =N35 -> -42217 | P35: =O35 -> -42217 | U35: Principal | V35: =990000-29940 -> 960060 | W35: =V35-W36 -> 928623 | X35: =W35-X36 -> 895614
B36: Revenue Growth of about 15% per year | L36: Net issues of Stock | M36: 0 | N36: 0 | O36: 0 | P36: 0 | U36: paid | V36: 29940 | W36: 31437 | X36: 33009
C37: Unit Demand | E37: 126869 | L37: (Dividends - Owner Draws) | M37: -175000 | N37: =IF(N18>175000,-175000,0) -> -175000 | O37: =IF(O18>175000,-175000,0) -> -175000 | P37: =IF(P18>175000,-175000,0) -> -175000
C38: Average Selling Price | E38: 14 | L38: Cash Provided (used) by Financing Activities | M38: =SUM(M35:M37) -> -217217 | N38: =SUM(N35:N37) -> -217217 | O38: =SUM(O35:O37) -> -217217 | P38: =SUM(P35:P37) -> -217217
B39: COGS % as a % of Revenues | K39: Net increase (decrease) in cash | M39: =M29+M33+M38 -> 17441 | N39: =N29+N33+N38 -> 179376.93 | O39: =O29+O33+O38 -> 115681.68 | P39: =P29+P33+P38 -> 307223.35
B40: Selling Expense as a % of Revenues | T40: CF
...

Sheet PF Rent_No Growth
A1: Bubble and Bee Organic - Pro Forma Modeling Template | S1: Assumptions | T1: Income Statement | AA1: buy
S2: g(d) | T2: 0 | V2: 2015 | W2: 2016 | X2: 2017 | AA2: rent
A3: Balance Sheet | J3: Income Statement | U3: demand | V3: 126869 | W3: 126869 | X3: 126869
D4: 2013 | E4: 2014 | F4: 2015 | G4: 2016 | H4: 2017 | M4: 2014 | N4: 2015 | O4: 2016 | P4: 2017 | U4: avg price | V4: 14.25 | W4: 14.5 | X4: 14.75
A5: Assets | K5: Revenues | M5: 1776168 | N5: =V5 -> 1807883.2 | O5: =W5 -> 1839600.5 | P5: =X5 -> 1871317.8 | U5: Revenue | V5: =V3*V4 -> 1807883.2 | W5: =W3*W4 -> 1839600.5 | X5: =X3*X4 -> 1871317.8
B6: Current Assets | L6: Cost of Goods Sold | M6: 357597 | N6: =N5*V7 -> 361576.65 | O6: =O5*W7 -> 386316.1 | P6: =P5*X7 -> 392976.73
C7: Cash | D7: 25567 | E7: 43008 | F7: =E7+N40 -> 130073.63 | G7: =F7+O40 -> 186178.83 | H7: =G7+P40 -> 113795.14 | L7: Gross Margin | M7: =M5-M6 -> 1418571 | N7: =N5-N6 -> 1446306.6 | O7: =O5-O6 -> 1453284.4 | P7: =P5-P6 -> 1478341 | U7: COGS | V7: 0.2 | W7: 0.21 | X7: 0.21
C8: Receivables | D8: 32375 | E8: 35525 | F8: =N5*$V$23 -> 36157.665 | G8: =O5*$V$23 -> 36792.01 | H8: =P5*$V$23 -> 37426.355 | K8: Expenses | U8: OPEX
C9: Inventories | D9: 131250 | E9: 143937 | F9: =N5*$V$24 -> 144630.66 | G9: =O5*$V$24 -> 147168.04 | H9: =P5*$V$24 -> 149705.42 | L9: Extra Rent | U9: sales | V9: 0.25 | W9: 0.26 | X9: 0.27
C10: Total Current Assets | D10: =SUM(D7:D9) -> 189192 | E10: =SUM(E7:E9) -> 222470 | F10: =SUM(F7:F9) -> 310861.96 | G10: =SUM(G7:G9) -> 370138.89 | H10: =SUM(H7:H9) -> 300926.92 | L10: Selling | M10: 439512 | N10: =V9*N5 -> 451970.81 | O10: =W9*O5 -> 478296.13 | P10: =X9*P5 -> 505255.79 | U10: rev dep | V10: 0.05 | W10: 0.05 | X10: 0.05
B11: Fixed Assets | L11: General & Administrative Variable | M11: 82514 | N11: =V10*N5 -> 90394.163 | O11: =W10*O5 -> 91980.025 | P11: =X10*P5 -> 93565.888 | U11: sg&A (annual inc) | V11: 50000 | W11: 50000 | X11: 50000
C12: PP&E | D12: 395785 | E12: 470185 | F12: =E12-N32 -> 470185 | G12: =F12-O32 -> 570185 | H12: =G12-P32 -> 570185 | L12: General & Administrative Fixed | M12: 572776 | N12: =V12 -> 675000 | O12: =W12 -> 725000 | P12: =X12 -> 775000 | U12: rent | V12: 675000 | W12: 725000 | X12: 775000
C13: Less Depreciation | D13: 120221 | E13: 207442 | F13: =E13+N13 -> 302663 | G13: =F13+O13 -> 407884 | H13: =G13+P13 -> 513105 | L13: Depreciation | M13: 87221 | N13: =V14 -> 95221 | O13: =W14 -> 105221 | P13: =X14 -> 105221
C14: Total Fixed Assets | D14: =D12-D13 -> 275564 | E14: =E12-E13 -> 262743 | F14: =F12-F13 -> 167522 | G14: =G12-G13 -> 162301 | H14: =H12-H13 -> 57080 | L14: Total Expenses | M14: =SUM(M10:M13) -> 1182023 | N14: =SUM(N9:N13) -> 1312586 | O14: =SUM(O9:O13) -> 1400497.2 | P14: =SUM(P9:P13) -> 1479042.7 | Q14: =Q7-Q13 -> 0 | U14: Depr Base | V14: 95221 | W14: 105221 | X14: 105221
K15: EBIT | M15: =M7-M14 -> 236548 | N15: =N7-N14 -> 133720.62 | O15: =O7-O14 -> 52787.24 | P15: =P7-P14 -> -701.6575 | Q15: =Y50 -> 0 | U15: Bldg Buy | V15: 36667 | W15: 36667 | X15: 36667
B16: Total Assets | D16: =D10+D14 -> 464756 | E16: =E10+E14 -> 485213 | F16: =F10+F14 -> 478383.96 | G16: =G10+G14 -> 532439.89 | H16: =H10+H14 -> 358006.92 | L16: Net Interest Expense | M16: 7535
K17: Taxable Income | M17: =M15-M16 -> 229013 | N17: =N15-N16 -> 133720.62 | O17: =O15-O16 -> 52787.24 | P17: =P15-P16 -> -701.6575 | U17: Interest (bldg) | V17: 49500 | W17: 48003 | X17: 46431
A18: Liabilities & Shareholder's Equity | L18: Taxes | M18: 0 | N18: 0 | O18: 0 | P18: 0 | Q18: =Q16-Q17 -> 0
B19: Current Liabilities | K19: Net Income | M19: =M17-M18 -> 229013 | N19: =N17-N18 -> 133720.62 | O19: =O17-O18 -> 52787.24 | P19: =P17-P18 -> -701.6575
C20: Accounts Payable | D20: 44625 | E20: 53286 | F20: =N5*$V$31 -> 72315.33 | G20: =O5*$V$31 -> 73584.02 | H20: =P5*$V$31 -> 74852.71 | J20: Cash Flow Statement
C21: Accrued Liabilities | D21: 0 | E21: 0 | F21: =E21 -> 0 | G21: =F21 -> 0 | H21: =G21 -> 0 | U21: Balance Sheets
C22: Bank Loan | D22: 201796 | E22: 159579 | F22: 0 | G22: 0 | H22: 0 | K22: Cash Provided (used) by Operations | V22: % sales
C23: Total Current Liabilities | D23: =SUM(D20:D22) -> 246421 | E23: =SUM(E20:E22) -> 212865 | F23: =SUM(F20:F22) -> 72315.33 | G23: =SUM(G20:G22) -> 73584.02 | H23: =SUM(H20:H22) -> 74852.71 | K23: Net Income | M23: =M19 -> 229013 | N23: =N19 -> 133720.62 | O23: =O19 -> 52787.24 | P23: =P19 -> -701.6575 | U23: A/R | V23: 0.02
B24: Long Term Liabilities | D24: 0 | E24: 0 | F24: 0 | G24: 0 | H24: 0 | K24: Plus Depreciation | M24: =M13 -> 87221 | N24: =N13 -> 95221 | O24: =O13 -> 105221 | P24: =P13 -> 105221 | U24: inv | V24: 0.08
C25: Total Liabilities | D25: =D23+D24 -> 246421 | E25: =E23+E24 -> 212865 | F25: =F23+F24 -> 72315.33 | G25: =G23+G24 -> 73584.02 | H25: =H23+H24 -> 74852.71 | K25: Change in Working Capital
L26: Decrease (increase) in Receivables | M26: =D8-E8 -> -3150 | N26: =-(F8-E8) -> -632.665 | O26: =-(G8-F8) -> -634.345 | P26: =-(H8-G8) -> -634.345
B27: Shareholder's Equity | L27: Decrease (increase) in Inventory | M27: =D9-E9 -> -12687 | N27: =-(F9-E9) -> -693.66 | O27: =-(G9-F9) -> -2537.38 | P27: =-(H9-G9) -> -2537.38 | W27: 2015
C28: Member's Equity | D28: 150000 | E28: 150000 | F28: 150000 | G28: 150000 | H28: 150000 | L28: Increase (decrease) in Accts. Payable | M28: =E20-D20 -> 8661 | N28: =F20-E20 -> 19029.33 | O28: =G20-F20 -> 1268.69 | P28: =H20-G20 -> 1268.69 | U28: PPE | W28: 100000
C29: Retained Earnings | D29: 68335 | E29: 122348 | F29: =E29+(N19+N38) -> 256068.62 | G29: =F29+(O19+O38) -> 308855.86 | H29: =G29+(P19+P38) -> 133154.21 | L29: Increase (decrease) in Accrued Liabilities | M29: =E21-D21 -> 0 | N29: =M29 -> 0 | O29: =N29 -> 0 | P29: =O29 -> 0
C30: Total Shareholder's Equity | D30: =SUM(D28:D29) -> 218335 | E30: =SUM(E28:E29) -> 272348 | F30: =SUM(F28:F29) -> 406068.62 | G30: =SUM(G28:G29) -> 458855.86 | H30: =SUM(H28:H29) -> 283154.21 | L30: Cash Provided (used) by Operations | M30: =M23+M24+M26+M27+M28+M29 -> 309058 | N30: =N23+N24+N26+N27+N28+N29 -> 246644.63 | O30: =O23+O24+O26+O27+O28+O29 -> 156105.2 | P30: =P23+P24+P26+P27+P28+P29 -> 102616.31 | V30: 2015 | W30: 2016 | X30: 2017
K31: Cash Provided (used) by Investments | U31: A/P | V31: 0.04
B32: Total Liabilities and Shareholder's Equity | D32: =D25+D30 -> 464756 | E32: =E25+E30 -> 485213 | F32: =F25+F30 -> 478383.96 | G32: =G25+G30 -> 532439.89 | H32: =H25+H30 -> 358006.92 | K32: Additions to PP&E | M32: =D12-E12 -> -74400 | N32: 0 | O32: -100000 | P32: 0 | U32: current liabilities | V32: 600000 | W32: 600000 | X32: 600000
K33: Other Investments | M33: 0
M34: =SUM(M32:M33) -> -74400 | N34: =SUM(N32:N33) -> 0 | O34: =SUM(O32:O33) -> -100000 | P34: =SUM(P32:P33) -> 0 | U34: LTL
A35: Assumptions | E35: 2014 | F35: 2015 | G35: 2016 | H35: 2017 | K35: Cash Provided (used) by Financing Activities | L35: Cash Provided (used) by Investments | U35: Principal | V35: =990000-29940 -> 960060 | W35: =V35-W36 -> 928623 | X35: =W35-X36 -> 895614
B36: Revenue Growth of about 15% per year | L36: Additions (reductions) to Debt | M36: =E22-D22 -> -42217 | N36: -159579 | U36: paid | V36: 29940 | W36: 31437 | X36: 33009
C37: Unit Demand | E37: 126869 | L37: Net issues of Stock | M37: 0 | N37: 0 | O37: 0 | P37: 0
C38: Average Selling Price | E38: 14 | L38: (Dividends - Owner Draws) | M38: -175000 | N38: =IF(E7>175000,-175000,0) -> 0 | O38: =IF(F7>175000,-175000,0) -> 0 | P38: =IF(G7>175000,-175000,0) -> -175000
B39: COGS % as a % of Revenues | L39: Cash Provided (used) by Financing Activities | M39: =SUM(M36:M38) -> -217217 | N39: =SUM(N36:N38) -> -159579 | O39: =SUM(O36:O38) -> 0 | P39: =SUM(P36:P38) -> -175000
B40: Selling Expense as a % of Revenues | K40: Net increase (decrease) in cash | M40: =M30+M34+M39 -> 17441 | N40: =N30+N34+N39 -> 87065.63 | O40: =O30+O34+O39 -> 56105.205 | P40: =P30+P34+P39 -> -72383.693 | T40: CF
...

Sheet PF Rent Growth
A1: Bubble and Bee Organic - Pro Forma Modeling Template | S1: Assumptions | T1: Income Statement | AA1: buy
S2: g(d) | T2: 0.15 | V2: 2015 | W2: 2016 | X2: 2017 | AA2: rent
A3: Balance Sheet | J3: Income Statement | U3: demand | V3: =126869*(1+$T$2) -> 145899.35 | W3: =V3*(1+$T$2) -> 167784.25 | X3: =W3*(1+$T$2) -> 192951.89
D4: 2013 | E4: 2014 | F4: 2015 | G4: 2016 | H4: 2017 | M4: 2014 | N4: 2015 | O4: 2016 | P4: 2017 | U4: avg price | V4: 14.25 | W4: 14.5 | X4: 14.75
A5: Assets | K5: Revenues | L5: 15% growth | M5: 1776168 | N5: =M5*(1+$T$2) -> 2042593.2 | O5: =N5*(1+$T$2) -> 2348982.2 | P5: =O5*(1+$T$2) -> 2701329.5 | U5: Revenue | V5: =V3*V4 -> 2079065.7 | W5: =W3*W4 -> 2432871.7 | X5: =X3*X4 -> 2846040.4
B6: Current Assets | L6: Cost of Goods Sold | M6: 357597 | N6: =N5*V7 -> 408518.64 | O6: =O5*W7 -> 493286.26 | P6: =P5*X7 -> 567279.2
C7: Cash | D7: 25567 | E7: 43008 | F7: =E7+N40 -> 58346.008 | G7: =F7+O40 -> 167474.12 | H7: =G7+P40 -> 465958.14 | L7: Gross Margin | M7: =M5-M6 -> 1418571 | N7: =N5-N6 -> 1634074.6 | O7: =O5-O6 -> 1855695.9 | P7: =P5-P6 -> 2134050.3 | U7: COGS | V7: 0.2 | W7: 0.21 | X7: 0.21
C8: Receivables | D8: 32375 | E8: 35525 | F8: =N5*$V$23 -> 40851.864 | G8: =O5*$V$23 -> 46979.644 | H8: =P5*$V$23 -> 54026.59 | K8: Expenses | U8: OPEX
C9: Inventories | D9: 131250 | E9: 143937 | F9: =N5*$V$24 -> 163407.46 | G9: =O5*$V$24 -> 187918.57 | H9: =P5*$V$24 -> 216106.36 | U9: sales | V9: 0.25 | W9: 0.26 | X9: 0.27
C10: Total Current Assets | D10: =SUM(D7:D9) -> 189192 | E10: =SUM(E7:E9) -> 222470 | F10: =SUM(F7:F9) -> 262605.33 | G10: =SUM(G7:G9) -> 402372.33 | H10: =SUM(H7:H9) -> 736091.09 | L10: Selling | M10: 439512 | N10: =V9*N5 -> 510648.3 | O10: =W9*O5 -> 610735.37 | P10: =X9*P5 -> 729358.97 | U10: rev dep | V10: 0.05 | W10: 0.05 | X10: 0.05
B11: Fixed Assets | L11: General & Administrative Variable | M11: 82514 | N11: =V10*N5 -> 102129.66 | O11: =W10*O5 -> 117449.11 | P11: =X10*P5 -> 135066.48 | U11: sg&A (annual inc) | V11: 50000 | W11: 50000 | X11: 50000
C12: PP&E | D12: 395785 | E12: 470185 | F12: =E12-N32 -> 470185 | G12: =F12-O32 -> 570185 | H12: =G12-P32 -> 570185 | L12: General & Administrative Fixed | M12: 572776 | N12: =V12 -> 675000 | O12: =W12 -> 725000 | P12: =X12 -> 775000 | U12: rent | V12: 675000 | W12: 725000 | X12: 775000
C13: Less Depreciation | D13: 120221 | E13: 207442 | F13: =E13+N13 -> 302663 | G13: =F13+O13 -> 407884 | H13: =G13+P13 -> 513105 | L13: Depreciation | M13: 87221 | N13: =V14 -> 95221 | O13: =W14 -> 105221 | P13: =X14 -> 105221
C14: Total Fixed Assets | D14: =D12-D13 -> 275564 | E14: =E12-E13 -> 262743 | F14: =F12-F13 -> 167522 | G14: =G12-G13 -> 162301 | H14: =H12-H13 -> 57080 | K14: EBIT | L14: Total Expenses | M14: =SUM(M10:M13) -> 1182023 | N14: =SUM(N9:N13) -> 1382999 | O14: =SUM(O9:O13) -> 1558405.5 | P14: =SUM(P9:P13) -> 1744646.4 | Q14: =Q7-Q13 -> 0 | U14: Depr Base | V14: 95221 | W14: 105221 | X14: 105221
M15: =M7-M14 -> 236548 | N15: =N7-N14 -> 251075.6 | O15: =O7-O14 -> 297290.45 | P15: =P7-P14 -> 389403.87 | Q15: =Y50 -> 0 | U15: Bldg Buy | V15: 36667 | W15: 36667 | X15: 36667
B16: Total Assets | D16: =D10+D14 -> 464756 | E16: =E10+E14 -> 485213 | F16: =F10+F14 -> 430127.33 | G16: =G10+G14 -> 564673.33 | H16: =H10+H14 -> 793171.09 | L16: Net Interest Expense | M16: 7535
K17: Taxable Income | M17: =M15-M16 -> 229013 | N17: =N15-N16 -> 251075.6 | O17: =O15-O16 -> 297290.45 | P17: =P15-P16 -> 389403.87 | U17: Interest (bldg) | V17: 49500 | W17: 48003 | X17: 46431
A18: Liabilities & Shareholder's Equity | L18: Taxes | M18: 0 | N18: 0 | O18: 0 | P18: 0 | Q18: =Q16-Q17 -> 0
B19: Current Liabilities | K19: Net Income | M19: =M17-M18 -> 229013 | N19: =N17-N18 -> 251075.6 | O19: =O17-O18 -> 297290.45 | P19: =P17-P18 -> 389403.87
C20: Accounts Payable | D20: 44625 | E20: 53286 | F20: =N5*$V$31 -> 81703.728 | G20: =O5*$V$31 -> 93959.287 | H20: =P5*$V$31 -> 108053.18 | J20: Cash Flow Statement
C21: Accrued Liabilities | D21: 0 | E21: 0 | F21: =E21 -> 0 | G21: =F21 -> 0 | H21: =G21 -> 0 | U21: Balance Sheets
C22: Bank Loan | D22: 201796 | E22: 159579 | F22: 0 | G22: 0 | H22: 0 | K22: Cash Provided (used) by Operations | V22: % sales
C23: Total Current Liabilities | D23: =SUM(D20:D22) -> 246421 | E23: =SUM(E20:E22) -> 212865 | F23: =SUM(F20:F22) -> 81703.728 | G23: =SUM(G20:G22) -> 93959.287 | H23: =SUM(H20:H22) -> 108053.18 | K23: Net Income | M23: =M19 -> 229013 | N23: =N19 -> 251075.6 | O23: =O19 -> 297290.45 | P23: =P19 -> 389403.87 | U23: A/R | V23: 0.02
B24: Long Term Liabilities | D24: 0 | E24: 0 | F24: 0 | G24: 0 | H24: 0 | K24: Plus Depreciation | M24: =M13 -> 87221 | N24: =N13 -> 95221 | O24: =O13 -> 105221 | P24: =P13 -> 105221 | U24: inv | V24: 0.08
C25: Total Liabilities | D25: =D23+D24 -> 246421 | E25: =E23+E24 -> 212865 | F25: =F23+F24 -> 81703.728 | G25: =G23+G24 -> 93959.287 | H25: =H23+H24 -> 108053.18 | K25: Change in Working Capital
L26: Decrease (increase) in Receivables | M26: =D8-E8 -> -3150 | N26: =-(F8-E8) -> -5326.864 | O26: =-(G8-F8) -> -6127.7796 | P26: =-(H8-G8) -> -7046.9465
B27: Shareholder's Equity | L27: Decrease (increase) in Inventory | M27: =D9-E9 -> -12687 | N27: =-(F9-E9) -> -19470.456 | O27: =-(G9-F9) -> -24511.118 | P27: =-(H9-G9) -> -28187.786 | W27: 2015
C28: Member's Equity | D28: 150000 | E28: 150000 | F28: 150000 | G28: 150000 | H28: 150000 | L28: Increase (decrease) in Accts. Payable | M28: =E20-D20 -> 8661 | N28: =F20-E20 -> 28417.728 | O28: =G20-F20 -> 12255.559 | P28: =H20-G20 -> 14093.893 | U28: PPE | W28: 100000
C29: Retained Earnings | D29: 68335 | E29: 122348 | F29: =E29+(N19+N38) -> 198423.6 | G29: =F29+(O19+O38) -> 320714.05 | H29: =G29+(P19+P38) -> 535117.91 | L29: Increase (decrease) in Accrued Liabilities | M29: =E21-D21 -> 0 | N29: =M29 -> 0 | O29: =N29 -> 0 | P29: =O29 -> 0
C30: Total Shareholder's Equity | D30: =SUM(D28:D29) -> 218335 | E30: =SUM(E28:E29) -> 272348 | F30: =SUM(F28:F29) -> 348423.6 | G30: =SUM(G28:G29) -> 470714.05 | H30: =SUM(H28:H29) -> 685117.91 | L30: Cash Provided (used) by Operations | M30: =M23+M24+M26+M27+M28+M29 -> 309058 | N30: =N23+N24+N26+N27+N28+N29 -> 349917.01 | O30: =O23+O24+O26+O27+O28+O29 -> 384128.11 | P30: =P23+P24+P26+P27+P28+P29 -> 473484.03 | V30: 2015 | W30: 2016 | X30: 2017
K31: Cash Provided (used) by Investments | U31: A/P | V31: 0.04
B32: Total Liabilities and Shareholder's Equity | D32: =D25+D30 -> 464756 | E32: =E25+E30 -> 485213 | F32: =F25+F30 -> 430127.33 | G32: =G25+G30 -> 564673.33 | H32: =H25+H30 -> 793171.09 | K32: Additions to PP&E | M32: =D12-E12 -> -74400 | N32: 0 | O32: -100000 | P32: 0 | U32: current liabilities | V32: 600000 | W32: 600000 | X32: 600000
K33: Other Investments | M33: 0
M34: =SUM(M32:M33) -> -74400 | N34: =SUM(N32:N33) -> 0 | O34: =SUM(O32:O33) -> -100000 | P34: =SUM(P32:P33) -> 0 | U34: LTL
A35: Assumptions | E35: 2014 | F35: 2015 | G35: 2016 | H35: 2017 | K35: Cash Provided (used) by Financing Activities | L35: Cash Provided (used) by Investments | U35: Principal | V35: =990000-29940 -> 960060 | W35: =V35-W36 -> 928623 | X35: =W35-X36 -> 895614
B36: Revenue Growth of about 15% per year | L36: Additions (reductions) to Debt | M36: =E22-D22 -> -42217 | N36: -159579 | U36: paid | V36: 29940 | W36: 31437 | X36: 33009
C37: Unit Demand | E37: 126869 | L37: Net issues of Stock | M37: 0 | N37: 0 | O37: 0 | P37: 0
C38: Average Selling Price | E38: 14 | L38: (Dividends - Owner Draws) | M38: -175000 | N38: -175000 | O38: -175000 | P38: -175000
B39: COGS % as a % of Revenues | L39: Cash Provided (used) by Financing Activities | M39: =SUM(M36:M38) -> -217217 | N39: =SUM(N36:N38) -> -334579 | O39: =SUM(O36:O38) -> -175000 | P39: =SUM(P36:P38) -> -175000
B40: Selling Expense as a % of Revenues | K40: Net increase (decrease) in cash | M40: =M30+M34+M39 -> 17441 | N40: =N30+N34+N39 -> 15338.008 | O40: =O30+O34+O39 -> 109128.11 | P40: =P30+P34+P39 -> 298484.03 | T40: CF
...

Sheet PF Purchase_No Growth
A1: Bubble and Bee Organic - Pro Forma Modeling Template | S1: Assumptions | T1: Income Statement | AA1: buy
S2: g(d) | T2: 0.15 | V2: 2015 | W2: 2016 | X2: 2017 | AA2: rent
A3: Balance Sheet | J3: Income Statement | U3: demand | V3: 126869 | W3: 126869 | X3: 126869
D4: 2013 | E4: 2014 | F4: 2015 | G4: 2016 | H4: 2017 | M4: 2014 | N4: 2015 | O4: 2016 | P4: 2017 | U4: avg price | V4: 14.25 | W4: 14.5 | X4: 14.75
A5: Assets | K5: Revenues | M5: 1776168 | N5: =V5 -> 1807883.2 | O5: =W5 -> 1839600.5 | P5: =X5 -> 1871317.8 | U5: Revenue | V5: =V3*V4 -> 1807883.2 | W5: =W3*W4 -> 1839600.5 | X5: =X3*X4 -> 1871317.8
B6: Current Assets | L6: Cost of Goods Sold | M6: 357597 | N6: =N5*V7 -> 361576.65 | O6: =O5*W7 -> 386316.1 | P6: =P5*X7 -> 392976.73
C7: Cash | D7: 25567 | E7: 43008 | F7: =E7+N39 -> 15633.63 | G7: =F7+O39 -> 67298.835 | H7: =G7+P39 -> 165475.14 | L7: Gross Margin | M7: =M5-M6 -> 1418571 | N7: =N5-N6 -> 1446306.6 | O7: =O5-O6 -> 1453284.4 | P7: =P5-P6 -> 1478341 | U7: COGS | V7: 0.2 | W7: 0.21 | X7: 0.21
C8: Receivables | D8: 32375 | E8: 35525 | F8: =N5*$V$23 -> 36157.665 | G8: =O5*$V$23 -> 36792.01 | H8: =P5*$V$23 -> 37426.355 | K8: Expenses | U8: OPEX
C9: Inventories | D9: 131250 | E9: 143937 | F9: =N5*$V$24 -> 144630.66 | G9: =O5*$V$24 -> 147168.04 | H9: =P5*$V$24 -> 149705.42 | L9: Selling | M9: 439512 | N9: =V9*N5 -> 451970.81 | O9: =W9*O5 -> 478296.13 | P9: =X9*P5 -> 505255.79 | U9: sales | V9: 0.25 | W9: 0.26 | X9: 0.27
C10: Total Current Assets | D10: =SUM(D7:D9) -> 189192 | E10: =SUM(E7:E9) -> 222470 | F10: =SUM(F7:F9) -> 196421.96 | G10: =SUM(G7:G9) -> 251258.89 | H10: =SUM(H7:H9) -> 352606.92 | L10: General & Administrative Variable | M10: 82514 | N10: =V10*N5 -> 90394.163 | O10: =W10*O5 -> 91980.025 | P10: =X10*P5 -> 93565.888 | U10: rev dep | V10: 0.05 | W10: 0.05 | X10: 0.05
B11: Fixed Assets | L11: General & Administrative Fixed | M11: 572776 | N11: 600000 | O11: =N11+W11 -> 650000 | P11: =O11+X11 -> 700000 | U11: sg&A (annual inc) | V11: 50000 | W11: 50000 | X11: 50000
C12: PP&E | D12: 395785 | E12: 470185 | F12: =E12-N31 -> 1570185 | G12: =F12-O31 -> 1670185 | H12: =G12-P31 -> 1670185 | L12: Depreciation | M12: 87221 | N12: =V14+V15 -> 131888 | O12: =W14+W15 -> 141888 | P12: =X14+X15 -> 141888 | U12: rent | V12: 675000 | W12: 725000 | X12: 775000
C13: Less Depreciation | D13: 120221 | E13: 207442 | F13: =E13+N12 -> 339330 | G13: =F13+O12 -> 481218 | H13: =G13+P12 -> 623106 | L13: Total Expenses | M13: =SUM(M9:M12) -> 1182023 | N13: =SUM(N9:N12) -> 1274253 | O13: =SUM(O9:O12) -> 1362164.2 | P13: =SUM(P9:P12) -> 1440709.7
C14: Total Fixed Assets | D14: =D12-D13 -> 275564 | E14: =E12-E13 -> 262743 | F14: =F12-F13 -> 1230855 | G14: =G12-G13 -> 1188967 | H14: =H12-H13 -> 1047079 | K14: EBIT | M14: =M7-M13 -> 236548 | N14: =N7-N13 -> 172053.62 | O14: =O7-O13 -> 91120.24 | P14: =P7-P13 -> 37631.342 | Q14: =Q7-Q13 -> 0 | U14: Depr Base | V14: 95221 | W14: 105221 | X14: 105221
L15: Net Interest Expense | M15: 7535 | N15: =V17 -> 49500 | O15: =W17 -> 48003 | P15: =X17 -> 46431 | Q15: =Y50 -> 0 | U15: Bldg Buy | V15: 36667 | W15: 36667 | X15: 36667
B16: Total Assets | D16: =D10+D14 -> 464756 | E16: =E10+E14 -> 485213 | F16: =F10+F14 -> 1427277 | G16: =G10+G14 -> 1440225.9 | H16: =H10+H14 -> 1399685.9 | K16: Taxable Income | M16: =M14-M15 -> 229013 | N16: =N14-N15 -> 122553.62 | O16: =O14-O15 -> 43117.24 | P16: =P14-P15 -> -8799.6575
L17: Taxes | M17: 0 | N17: 0 | O17: 0 | P17: 0 | U17: Interest (bldg) | V17: 49500 | W17: 48003 | X17: 46431
A18: Liabilities & Shareholder's Equity | K18: Net Income | M18: =M16-M17 -> 229013 | N18: =N16-N17 -> 122553.62 | O18: =O16-O17 -> 43117.24 | P18: =P16-P17 -> -8799.6575 | Q18: =Q16-Q17 -> 0
B19: Current Liabilities | J19: Cash Flow Statement
C20: Accounts Payable | D20: 44625 | E20: 53286 | F20: =N5*$V$31 -> 72315.33 | G20: =O5*$V$31 -> 73584.02 | H20: =P5*$V$31 -> 74852.71
C21: Accrued Liabilities | D21: 0 | E21: 0 | F21: =E21 -> 0 | G21: =F21 -> 0 | H21: =G21 -> 0 | K21: Cash Provided (used) by Operations | U21: Balance Sheets
C22: Bank Loan | D22: 201796 | E22: 159579 | K22: Net Income | M22: =M18 -> 229013 | N22: =N18 -> 122553.62 | O22: =O18 -> 43117.24 | P22: =P18 -> -8799.6575 | V22: % sales
C23: Total Current Liabilities | D23: =SUM(D20:D22) -> 246421 | E23: =SUM(E20:E22) -> 212865 | F23: =SUM(F20:F22) -> 72315.33 | G23: =SUM(G20:G22) -> 73584.02 | H23: =SUM(H20:H22) -> 74852.71 | K23: Plus Depreciation | M23: =M12 -> 87221 | N23: =N12 -> 131888 | O23: =O12 -> 141888 | P23: =P12 -> 141888 | U23: A/R | V23: 0.02
B24: Long Term Liabilities | D24: 0 | E24: 0 | F24: 960060 | G24: 928623 | H24: 895614 | K24: Change in Working Capital | U24: inv | V24: 0.08
C25: Total Liabilities | D25: =D23+D24 -> 246421 | E25: =E23+E24 -> 212865 | F25: =F23+F24 -> 1032375.3 | G25: =G23+G24 -> 1002207 | H25: =H23+H24 -> 970466.71 | L25: Decrease (increase) in Receivables | M25: =D8-E8 -> -3150 | N25: =-(F8-E8) -> -632.665 | O25: =-(G8-F8) -> -634.345 | P25: =-(H8-G8) -> -634.345
L26: Decrease (increase) in Inventory | M26: =D9-E9 -> -12687 | N26: =-(F9-E9) -> -693.66 | O26: =-(G9-F9) -> -2537.38 | P26: =-(H9-G9) -> -2537.38
B27: Shareholder's Equity | L27: Increase (decrease) in Accts. Payable | M27: =E20-D20 -> 8661 | N27: =F20-E20 -> 19029.33 | O27: =G20-F20 -> 1268.69 | P27: =H20-G20 -> 1268.69 | W27: 2015
C28: Member's Equity | D28: 150000 | E28: 150000 | F28: 150000 | G28: 150000 | H28: 150000 | L28: Increase (decrease) in Accrued Liabilities | M28: =E21-D21 -> 0 | N28: =M28 -> 0 | O28: =N28 -> 0 | P28: =O28 -> 0 | U28: PPE | W28: 100000
C29: Retained Earnings | D29: 68335 | E29: 122348 | F29: =E29+(N18+N37) -> 244901.62 | G29: =F29+(O18+O37) -> 288018.86 | H29: =G29+(P18+P37) -> 279219.21 | L29: Cash Provided (used) by Operations | M29: =M22+M23+M25+M26+M27+M28 -> 309058 | N29: =N22+N23+N25+N26+N27+N28 -> 272144.63 | O29: =O22+O23+O25+O26+O27+O28 -> 183102.2 | P29: =P22+P23+P25+P26+P27+P28 -> 131185.31
C30: Total Shareholder's Equity | D30: =SUM(D28:D29) -> 218335 | E30: =SUM(E28:E29) -> 272348 | F30: =SUM(F28:F29) -> 394901.62 | G30: =SUM(G28:G29) -> 438018.86 | H30: =SUM(H28:H29) -> 429219.21 | K30: Cash Provided (used) by Investments | V30: 2015 | W30: 2016 | X30: 2017
K31: Additions to PP&E | M31: =D12-E12 -> -74400 | N31: -1100000 | O31: -100000 | P31: 0 | U31: A/P | V31: 0.04
B32: Total Liabilities and Shareholder's Equity | D32: =D25+D30 -> 464756 | E32: =E25+E30 -> 485213 | F32: =F25+F30 -> 1427277 | G32: =G25+G30 -> 1440225.9 | H32: =H25+H30 -> 1399685.9 | K32: Other Investments | M32: 0 | U32: current liabilities | V32: 600000 | W32: 600000 | X32: 600000
L33: Cash Provided (used) by Investments | M33: =SUM(M31:M32) -> -74400 | N33: =SUM(N31:N32) -> -1100000 | O33: =SUM(O31:O32) -> -100000 | P33: =SUM(P31:P32) -> 0
K34: Cash Provided (used) by Financing Activities | U34: LTL
A35: Assumptions | E35: 2014 | F35: 2015 | G35: 2016 | H35: 2017 | L35: Additions (reductions) to Debt | M35: =E22-D22 -> -42217 | N35: 800481 | O35: 31437 | P35: 33009 | U35: Principal | V35: =990000-29940 -> 960060 | W35: =V35-W36 -> 928623 | X35: =W35-X36 -> 895614
B36: Revenue Growth of about 15% per year | L36: Net issues of Stock | M36: 0 | N36: 0 | O36: 0 | P36: 0 | U36: paid | V36: 29940 | W36: 31437 | X36: 33009
C37: Unit Demand | E37: 126869 | L37: (Dividends - Owner Draws) | M37: -175000 | N37: =IF(N18>175000,-175000,0) -> 0 | O37: =IF(O18>175000,-175000,0) -> 0 | P37: =IF(P18>175000,-175000,0) -> 0
C38: Average Selling Price | E38: 14 | L38: Cash Provided (used) by Financing Activities | M38: =SUM(M35:M37) -> -217217 | N38: =SUM(N35:N37) -> 800481 | O38: =SUM(O35:O37) -> 31437 | P38: =SUM(P35:P37) -> 33009
B39: COGS % as a % of Revenues | K39: Net increase (decrease) in cash | M39: =M29+M33+M38 -> 17441 | N39: =N29+N33+N38 -> -27374.37 | O39: =O29+O33-O35 -> 51665.205 | P39: =P29+P33-P35 -> 98176.307
B40: Selling Expense as a % of Revenues | T40: CF
...

Sheet PF Purchase Growth
A1: Bubble and Bee Organic - Pro Forma Modeling Template | S1: Assumptions | T1: Income Statement | AA1: buy
S2: g(d) | T2: 0.15 | V2: 2015 | W2: 2016 | X2: 2017 | AA2: rent
A3: Balance Sheet | J3: Income Statement | U3: demand | V3: 126869 | W3: 126869 | X3: 126869
D4: 2013 | E4: 2014 | F4: 2015 | G4: 2016 | H4: 2017 | M4: 2014 | N4: 2015 | O4: 2016 | P4: 2017 | U4: avg price | V4: 14.25 | W4: 14.5 | X4: 14.75
A5: Assets | K5: Revenues (grow at 15%) | M5: 1776168 | N5: =M5*1.15 -> 2042593.2 | O5: =N5*1.15 -> 2348982.2 | P5: =O5*1.15 -> 2701329.5 | U5: Revenue | V5: =V3*V4 -> 1807883.2 | W5: =W3*W4 -> 1839600.5 | X5: =X3*X4 -> 1871317.8
B6: Current Assets | L6: Cost of Goods Sold | M6: 357597 | N6: =N5*V7 -> 408518.64 | O6: =O5*W7 -> 493286.26 | P6: =P5*X7 -> 567279.2
C7: Cash | D7: 25567 | E7: 43008 | F7: =E7+N39 -> 118906.01 | G7: =F7+O39 -> 223594.12 | H7: =G7+P39 -> 517638.14 | L7: Gross Margin | M7: =M5-M6 -> 1418571 | N7: =N5-N6 -> 1634074.6 | O7: =O5-O6 -> 1855695.9 | P7: =P5-P6 -> 2134050.3 | U7: COGS | V7: 0.2 | W7: 0.21 | X7: 0.21
C8: Receivables | D8: 32375 | E8: 35525 | F8: =N5*$V$23 -> 40851.864 | G8: =O5*$V$23 -> 46979.644 | H8: =P5*$V$23 -> 54026.59 | K8: Expenses | U8: OPEX
C9: Inventories | D9: 131250 | E9: 143937 | F9: =N5*$V$24 -> 163407.46 | G9: =O5*$V$24 -> 187918.57 | H9: =P5*$V$24 -> 216106.36 | L9: Selling | M9: 439512 | N9: =V9*N5 -> 510648.3 | O9: =W9*O5 -> 610735.37 | P9: =X9*P5 -> 729358.97 | U9: sales | V9: 0.25 | W9: 0.26 | X9: 0.27
C10: Total Current Assets | D10: =SUM(D7:D9) -> 189192 | E10: =SUM(E7:E9) -> 222470 | F10: =SUM(F7:F9) -> 323165.33 | G10: =SUM(G7:G9) -> 458492.33 | H10: =SUM(H7:H9) -> 787771.09 | L10: General & Administrative Variable | M10: 82514 | N10: =V10*N5 -> 102129.66 | O10: =W10*O5 -> 117449.11 | P10: =X10*P5 -> 135066.48 | U10: rev dep | V10: 0.05 | W10: 0.05 | X10: 0.05
B11: Fixed Assets | L11: General & Administrative Fixed | M11: 572776 | N11: 600000 | O11: =N11+W11 -> 650000 | P11: =O11+X11 -> 700000 | U11: sg&A (annual inc) | V11: 50000 | W11: 50000 | X11: 50000
C12: PP&E | D12: 395785 | E12: 470185 | F12: =E12-N31 -> 1570185 | G12: =F12-O31 -> 1670185 | H12: =G12-P31 -> 1670185 | L12: Depreciation | M12: 87221 | N12: =V14+V15 -> 131888 | O12: =W14+W15 -> 141888 | P12: =X14+X15 -> 141888 | U12: rent | V12: 675000 | W12: 725000 | X12: 775000
C13: Less Depreciation | D13: 120221 | E13: 207442 | F13: =E13+N12 -> 339330 | G13: =F13+O12 -> 481218 | H13: =G13+P12 -> 623106 | L13: Total Expenses | M13: =SUM(M9:M12) -> 1182023 | N13: =SUM(N9:N12) -> 1344666 | O13: =SUM(O9:O12) -> 1520072.5 | P13: =SUM(P9:P12) -> 1706313.4
C14: Total Fixed Assets | D14: =D12-D13 -> 275564 | E14: =E12-E13 -> 262743 | F14: =F12-F13 -> 1230855 | G14: =G12-G13 -> 1188967 | H14: =H12-H13 -> 1047079 | K14: EBIT | M14: =M7-M13 -> 236548 | N14: =N7-N13 -> 289408.6 | O14: =O7-O13 -> 335623.45 | P14: =P7-P13 -> 427736.87 | Q14: =Q7-Q13 -> 0 | U14: Depr Base | V14: 95221 | W14: 105221 | X14: 105221
L15: Net Interest Expense | M15: 7535 | N15: =V17 -> 49500 | O15: =W17 -> 48003 | P15: =X17 -> 46431 | Q15: =Y50 -> 0 | U15: Bldg Buy | V15: 36667 | W15: 36667 | X15: 36667
B16: Total Assets | D16: =D10+D14 -> 464756 | E16: =E10+E14 -> 485213 | F16: =F10+F14 -> 1554020.3 | G16: =G10+G14 -> 1647459.3 | H16: =H10+H14 -> 1834850.1 | K16: Taxable Income | M16: =M14-M15 -> 229013 | N16: =N14-N15 -> 239908.6 | O16: =O14-O15 -> 287620.45 | P16: =P14-P15 -> 381305.87
L17: Taxes | M17: 0 | N17: 0 | O17: 0 | P17: 0 | U17: Interest (bldg) | V17: 49500 | W17: 48003 | X17: 46431
A18: Liabilities & Shareholder's Equity | K18: Net Income | M18: =M16-M17 -> 229013 | N18: =N16-N17 -> 239908.6 | O18: =O16-O17 -> 287620.45 | P18: =P16-P17 -> 381305.87 | Q18: =Q16-Q17 -> 0
B19: Current Liabilities | J19: Cash Flow Statement
C20: Accounts Payable | D20: 44625 | E20: 53286 | F20: =N5*$V$31 -> 81703.728 | G20: =O5*$V$31 -> 93959.287 | H20: =P5*$V$31 -> 108053.18
C21: Accrued Liabilities | D21: 0 | E21: 0 | F21: =E21 -> 0 | G21: =F21 -> 0 | H21: =G21 -> 0 | K21: Cash Provided (used) by Operations | U21: Balance Sheets
C22: Bank Loan | D22: 201796 | E22: 159579 | K22: Net Income | M22: =M18 -> 229013 | N22: =N18 -> 239908.6 | O22: =O18 -> 287620.45 | P22: =P18 -> 381305.87 | V22: % sales
C23: Total Current Liabilities | D23: =SUM(D20:D22) -> 246421 | E23: =SUM(E20:E22) -> 212865 | F23: =SUM(F20:F22) -> 81703.728 | G23: =SUM(G20:G22) -> 93959.287 | H23: =SUM(H20:H22) -> 108053.18 | K23: Plus Depreciation | M23: =M12 -> 87221 | N23: =N12 -> 131888 | O23: =O12 -> 141888 | P23: =P12 -> 141888 | U23: A/R | V23: 0.02
B24: Long Term Liabilities | D24: 0 | E24: 0 | F24: 960060 | G24: 928623 | H24: 895614 | K24: Change in Working Capital | U24: inv | V24: 0.08
C25: Total Liabilities | D25: =D23+D24 -> 246421 | E25: =E23+E24 -> 212865 | F25: =F23+F24 -> 1041763.7 | G25: =G23+G24 -> 1022582.3 | H25: =H23+H24 -> 1003667.2 | L25: Decrease (increase) in Receivables | M25: =D8-E8 -> -3150 | N25: =-(F8-E8) -> -5326.864 | O25: =-(G8-F8) -> -6127.7796 | P25: =-(H8-G8) -> -7046.9465
L26: Decrease (increase) in Inventory | M26: =D9-E9 -> -12687 | N26: =-(F9-E9) -> -19470.456 | O26: =-(G9-F9) -> -24511.118 | P26: =-(H9-G9) -> -28187.786
B27: Shareholder's Equity | L27: Increase (decrease) in Accts. Payable | M27: =E20-D20 -> 8661 | N27: =F20-E20 -> 28417.728 | O27: =G20-F20 -> 12255.559 | P27: =H20-G20 -> 14093.893 | W27: 2015
C28: Member's Equity | D28: 150000 | E28: 150000 | F28: 150000 | G28: 150000 | H28: 150000 | L28: Increase (decrease) in Accrued Liabilities | M28: =E21-D21 -> 0 | N28: =M28 -> 0 | O28: =N28 -> 0 | P28: =O28 -> 0 | U28: PPE | W28: 100000
C29: Retained Earnings | D29: 68335 | E29: 122348 | F29: =E29+(N18+N37) -> 362256.6 | G29: =F29+(O18+O37) -> 474877.05 | H29: =G29+(P18+P37) -> 681182.91 | L29: Cash Provided (used) by Operations | M29: =M22+M23+M25+M26+M27+M28 -> 309058 | N29: =N22+N23+N25+N26+N27+N28 -> 375417.01 | O29: =O22+O23+O25+O26+O27+O28 -> 411125.11 | P29: =P22+P23+P25+P26+P27+P28 -> 502053.03
C30: Total Shareholder's Equity | D30: =SUM(D28:D29) -> 218335 | E30: =SUM(E28:E29) -> 272348 | F30: =SUM(F28:F29) -> 512256.6 | G30: =SUM(G28:G29) -> 624877.05 | H30: =SUM(H28:H29) -> 831182.91 | K30: Cash Provided (used) by Investments | V30: 2015 | W30: 2016 | X30: 2017
K31: Additions to PP&E | M31: =D12-E12 -> -74400 | N31: -1100000 | O31: -100000 | P31: 0 | U31: A/P | V31: 0.04
B32: Total Liabilities and Shareholder's Equity | D32: =D25+D30 -> 464756 | E32: =E25+E30 -> 485213 | F32: =F25+F30 -> 1554020.3 | G32: =G25+G30 -> 1647459.3 | H32: =H25+H30 -> 1834850.1 | K32: Other Investments | M32: 0 | U32: current liabilities | V32: 600000 | W32: 600000 | X32: 600000
L33: Cash Provided (used) by Investments | M33: =SUM(M31:M32) -> -74400 | N33: =SUM(N31:N32) -> -1100000 | O33: =SUM(O31:O32) -> -100000 | P33: =SUM(P31:P32) -> 0
K34: Cash Provided (used) by Financing Activities | U34: LTL
A35: Assumptions | E35: 2014 | F35: 2015 | G35: 2016 | H35: 2017 | L35: Additions (reductions) to Debt | M35: =E22-D22 -> -42217 | N35: 800481 | O35: -31437 | P35: -33009 | U35: Principal | V35: =990000-29940 -> 960060 | W35: =V35-W36 -> 928623 | X35: =W35-X36 -> 895614
B36: Revenue Growth of about 15% per year | L36: Net issues of Stock | M36: 0 | N36: 0 | O36: 0 | P36: 0 | U36: paid | V36: 29940 | W36: 31437 | X36: 33009
C37: Unit Demand | E37: 126869 | L37: (Dividends - Owner Draws) | M37: -175000 | O37: =IF(O18>175000,-175000,0) -> -175000 | P37: =IF(P18>175000,-175000,0) -> -175000
C38: Average Selling Price | E38: 14 | L38: Cash Provided (used) by Financing Activities | M38: =SUM(M35:M37) -> -217217 | N38: =SUM(N35:N37) -> 800481 | O38: =SUM(O35:O37) -> -206437 | P38: =SUM(P35:P37) -> -208009
B39: COGS % as a % of Revenues | K39: Net increase (decrease) in cash | M39: =M29+M33+M38 -> 17441 | N39: =N29+N33+N38 -> 75898.008 | O39: =O29+O33+O38 -> 104688.11 | P39: =P29+P33+P38 -> 294044.03
B40: Selling Expense as a % of Revenues | T40: CF
...

Sheet PF Purchase_CCorp
A1: Bubble and Bee Organic - Pro Forma Modeling Template | S1: Assumptions | T1: Income Statement | AA1: buy
S2: g(d) | T2: 0.15 | V2: 2015 | W2: 2016 | X2: 2017 | AA2: rent
A3: Balance Sheet | J3: Income Statement | U3: demand | V3: 126869 | W3: 126869 | X3: 126869
D4: 2013 | E4: 2014 | F4: 2015 | G4: 2016 | H4: 2017 | M4: 2014 | N4: 2015 | O4: 2016 | P4: 2017 | U4: avg price | V4: 14.25 | W4: 14.5 | X4: 14.75
A5: Assets | K5: Revenues (grow at 15%) | M5: 1776168 | N5: =M5*1.15 -> 2042593.2 | O5: =N5*1.15 -> 2348982.2 | P5: =O5*1.15 -> 2701329.5 | U5: Revenue | V5: =V3*V4 -> 1807883.2 | W5: =W3*W4 -> 1839600.5 | X5: =X3*X4 -> 1871317.8
B6: Current Assets | L6: Cost of Goods Sold | M6: 357597 | N6: =N5*V7 -> 408518.64 | O6: =O5*W7 -> 493286.26 | P6: =P5*X7 -> 567279.2
C7: Cash | D7: 25567 | E7: 43008 | F7: =E7+N40 -> -72321.142 | G7: =F7+O40 -> 4211.854 | H7: =G7+P40 -> 246679.42 | L7: Gross Margin | M7: =M5-M6 -> 1418571 | N7: =N5-N6 -> 1634074.6 | O7: =O5-O6 -> 1855695.9 | P7: =P5-P6 -> 2134050.3 | U7: COGS | V7: 0.2 | W7: 0.21 | X7: 0.21
C8: Receivables | D8: 32375 | E8: 35525 | F8: =N5*$V$23 -> 40851.864 | G8: =O5*$V$23 -> 46979.644 | H8: =P5*$V$23 -> 54026.59 | K8: Expenses | U8: OPEX
C9: Inventories | D9: 131250 | E9: 143937 | F9: =N5*$V$24 -> 163407.46 | G9: =O5*$V$24 -> 187918.57 | H9: =P5*$V$24 -> 216106.36 | L9: Selling | M9: 439512 | N9: =V9*N5 -> 510648.3 | O9: =W9*O5 -> 610735.37 | P9: =X9*P5 -> 729358.97 | U9: sales | V9: 0.25 | W9: 0.26 | X9: 0.27
C10: Total Current Assets | D10: =SUM(D7:D9) -> 189192 | E10: =SUM(E7:E9) -> 222470 | F10: =SUM(F7:F9) -> 131938.18 | G10: =SUM(G7:G9) -> 239110.07 | H10: =SUM(H7:H9) -> 516812.37 | L10: General & Administrative Variable | M10: 82514 | N10: =V10*N5 -> 102129.66 | O10: =W10*O5 -> 117449.11 | P10: =X10*P5 -> 135066.48 | U10: rev dep | V10: 0.05 | W10: 0.05 | X10: 0.05
B11: Fixed Assets | L11: Wages | N11: 175000 | O11: 175000 | P11: 175000 | U11: sg&A (annual inc) | V11: 50000 | W11: 50000 | X11: 50000
C12: PP&E | D12: 395785 | E12: 470185 | F12: =E12-N32 -> 1570185 | G12: =F12-O32 -> 1670185 | H12: =G12-P32 -> 1670185 | L12: General & Administrative Fixed | M12: 572776 | N12: 600000 | O12: =N12+W11 -> 650000 | P12: =O12+X11 -> 700000 | U12: rent | V12: 675000 | W12: 725000 | X12: 775000
C13: Less Depreciation | D13: 120221 | E13: 207442 | F13: =E13+N13 -> 339330 | G13: =F13+O13 -> 481218 | H13: =G13+P13 -> 623106 | L13: Depreciation | M13: 87221 | N13: =V14+V15 -> 131888 | O13: =W14+W15 -> 141888 | P13: =X14+X15 -> 141888
C14: Total Fixed Assets | D14: =D12-D13 -> 275564 | E14: =E12-E13 -> 262743 | F14: =F12-F13 -> 1230855 | G14: =G12-G13 -> 1188967 | H14: =H12-H13 -> 1047079 | L14: Total Expenses | M14: =SUM(M9:M13) -> 1182023 | N14: =SUM(N9:N13) -> 1519666 | O14: =SUM(O9:O13) -> 1695072.5 | P14: =SUM(P9:P13) -> 1881313.4 | Q14: =Q7-Q13 -> 0 | U14: Depr Base | V14: 95221 | W14: 105221 | X14: 105221
K15: EBIT | M15: =M7-M14 -> 236548 | N15: =N7-N14 -> 114408.6 | O15: =O7-O14 -> 160623.45 | P15: =P7-P14 -> 252736.87 | Q15: =Y50 -> 0 | U15: Bldg Buy | V15: 36667 | W15: 36667 | X15: 36667
B16: Total Assets | D16: =D10+D14 -> 464756 | E16: =E10+E14 -> 485213 | F16: =F10+F14 -> 1362793.2 | G16: =G10+G14 -> 1428077.1 | H16: =H10+H14 -> 1563891.4 | L16: Net Interest Expense | M16: 7535 | N16: =V17 -> 49500 | O16: =W17 -> 48003 | P16: =X17 -> 46431
K17: Taxable Income | M17: =M15-M16 -> 229013 | N17: =N15-N16 -> 64908.6 | O17: =O15-O16 -> 112620.45 | P17: =P15-P16 -> 206305.87 | U17: Interest (bldg) | V17: 49500 | W17: 48003 | X17: 46431
A18: Liabilities & Shareholder's Equity | L18: Taxes | M18: 0.25 | N18: =$M$18*N17 -> 16227.15 | O18: =$M$18*O17 -> 28155.112 | P18: =$M$18*P17 -> 51576.467 | Q18: =Q16-Q17 -> 0
B19: Current Liabilities | K19: Net Income | M19: =M17-M18 -> 229012.75 | N19: =N17-N18 -> 48681.45 | O19: =O17-O18 -> 84465.335 | P19: =P17-P18 -> 154729.4
C20: Accounts Payable | D20: 44625 | E20: 53286 | F20: =N5*$V$31 -> 81703.728 | G20: =O5*$V$31 -> 93959.287 | H20: =P5*$V$31 -> 108053.18 | J20: Cash Flow Statement
C21: Accrued Liabilities | D21: 0 | E21: 0 | F21: =E21 -> 0 | G21: =F21 -> 0 | H21: =G21 -> 0 | U21: Balance Sheets
C22: Bank Loan | D22: 201796 | E22: 159579 | K22: Cash Provided (used) by Operations | V22: % sales
C23: Total Current Liabilities | D23: =SUM(D20:D22) -> 246421 | E23: =SUM(E20:E22) -> 212865 | F23: =SUM(F20:F22) -> 81703.728 | G23: =SUM(G20:G22) -> 93959.287 | H23: =SUM(H20:H22) -> 108053.18 | K23: Net Income | M23: =M19 -> 229012.75 | N23: =N19 -> 48681.45 | O23: =O19 -> 84465.335 | P23: =P19 -> 154729.4 | U23: A/R | V23: 0.02
B24: Long Term Liabilities | D24: 0 | E24: 0 | F24: 960060 | G24: 928623 | H24: 895614 | K24: Plus Depreciation | M24: =M13 -> 87221 | N24: =N13 -> 131888 | O24: =O13 -> 141888 | P24: =P13 -> 141888 | U24: inv | V24: 0.08
C25: Total Liabilities | D25: =D23+D24 -> 246421 | E25: =E23+E24 -> 212865 | F25: =F23+F24 -> 1041763.7 | G25: =G23+G24 -> 1022582.3 | H25: =H23+H24 -> 1003667.2 | K25: Change in Working Capital
L26: Decrease (increase) in Receivables | M26: =D8-E8 -> -3150 | N26: =-(F8-E8) -> -5326.864 | O26: =-(G8-F8) -> -6127.7796 | P26: =-(H8-G8) -> -7046.9465
B27: Shareholder's Equity | L27: Decrease (increase) in Inventory | M27: =D9-E9 -> -12687 | N27: =-(F9-E9) -> -19470.456 | O27: =-(G9-F9) -> -24511.118 | P27: =-(H9-G9) -> -28187.786 | W27: 2015
C28: Member's Equity | D28: 150000 | E28: 150000 | F28: 150000 | G28: 150000 | H28: 150000 | L28: Increase (decrease) in Accts. Payable | M28: =E20-D20 -> 8661 | N28: =F20-E20 -> 28417.728 | O28: =G20-F20 -> 12255.559 | P28: =H20-G20 -> 14093.893 | U28: PPE | W28: 100000
C29: Retained Earnings | D29: 68335 | E29: 122348 | F29: =E29+(N19+N38) -> 171029.45 | G29: =F29+(O19+O38) -> 255494.78 | H29: =G29+(P19+P38) -> 410224.19 | L29: Increase (decrease) in Accrued Liabilities | M29: =E21-D21 -> 0 | N29: =M29 -> 0 | O29: =N29 -> 0 | P29: =O29 -> 0
C30: Total Shareholder's Equity | D30: =SUM(D28:D29) -> 218335 | E30: =SUM(E28:E29) -> 272348 | F30: =SUM(F28:F29) -> 321029.45 | G30: =SUM(G28:G29) -> 405494.78 | H30: =SUM(H28:H29) -> 560224.19 | L30: Cash Provided (used) by Operations | M30: =M23+M24+M26+M27+M28+M29 -> 309057.75 | N30: =N23+N24+N26+N27+N28+N29 -> 184189.86 | O30: =O23+O24+O26+O27+O28+O29 -> 207970 | P30: =P23+P24+P26+P27+P28+P29 -> 275476.56 | V30: 2015 | W30: 2016 | X30: 2017
K31: Cash Provided (used) by Investments | U31: A/P | V31: 0.04
B32: Total Liabilities and Shareholder's Equity | D32: =D25+D30 -> 464756 | E32: =E25+E30 -> 485213 | F32: =F25+F30 -> 1362793.2 | G32: =G25+G30 -> 1428077.1 | H32: =H25+H30 -> 1563891.4 | K32: Additions to PP&E | M32: =D12-E12 -> -74400 | N32: -1100000 | O32: -100000 | P32: 0 | U32: current liabilities | V32: 600000 | W32: 600000 | X32: 600000
K33: Other Investments | M33: 0
L34: Cash Provided (used) by Investments | M34: =SUM(M32:M33) -> -74400 | N34: =SUM(N32:N33) -> -1100000 | O34: =SUM(O32:O33) -> -100000 | P34: =SUM(P32:P33) -> 0 | U34: LTL
A35: Assumptions | E35: 2014 | F35: 2015 | G35: 2016 | H35: 2017 | K35: Cash Provided (used) by Financing Activities | U35: Principal | V35: =990000-29940 -> 960060 | W35: =V35-W36 -> 928623 | X35: =W35-X36 -> 895614
B36: Revenue Growth of about 15% per year | L36: Additions (reductions) to Debt | M36: =E22-D22 -> -42217 | N36: 800481 | O36: -31437 | P36: -33009 | U36: paid | V36: 29940 | W36: 31437 | X36: 33009
C37: Unit Demand | E37: 126869 | L37: Net issues of Stock | M37: 0 | N37: 0 | O37: 0 | P37: 0
C38: Average Selling Price | E38: 14 | L38: (Dividends - Owner Draws) | M38: -175000
B39: COGS % as a % of Revenues | L39: Cash Provided (used) by Financing Activities | M39: =SUM(M36:M38) -> -217217 | N39: =SUM(N36:N38) -> 800481 | O39: =SUM(O36:O38) -> -31437 | P39: =SUM(P36:P38) -> -33009
B40: Selling Expense as a % of Revenues | K40: Net increase (decrease) in cash | M40: =M30+M34+M39 -> 17440.75 | N40: =N30+N34+N39 -> -115329.14 | O40: =O30+O34+O39 -> 76532.996 | P40: =P30+P34+P39 -> 242467.56 | T40: CF
...

Sheet Loan Details
A2: Loan | B2: = | C2: 0.9
A3: Value
C5: =C2*C6 -> 990000
C6: 1100000
A9: pre tax cost of debt
A10: after tax cost of debt
A13: Depreciation
A14: value of depreciation
A17: She is losing the tax advantages.
A19: Look at LLC and C Corp implications
A23: Loan Amortization | B23: 2015 | C23: 2016 | D23: 2017
B24: =990000-B25 -> 960000 | C24: =B24-B25 -> 930000 | D24: =C24-C25 -> 897059.84
A25: Principal | B25: 30000 | C25: =-B31-C26 -> 32940.161 | D25: =-B31-D26 -> 34587.169
A26: Interest | B26: =0.05*B30 -> 49500 | C26: =0.05*C24 -> 46500 | D26: =0.05*D24 -> 44852.992
A28: N | B28: 20
A29: r | B29: 0.05
A30: PV | B30: 990000
A31: PMT | B31: =PMT(B29,B28,B30,B32,0) -> -79440.161
A32: FV | B32: 0

Sheet Pro Forma Modeling Template
A1: Bubble and Bee Organic - Pro Forma Modeling Template
A3: Balance Sheet | J3: Income Statement
D4: 2013 | E4: 2014 | F4: 2015 | G4: 2016 | H4: 2017 | M4: 2014 | N4: 2015 | O4: 2016 | P4: 2017
A5: Assets | K5: Revenues | M5: 1776168
B6: Current Assets | L6: Cost of Goods Sold | M6: 357597
C7: Cash | D7: 25567 | E7: 43008 | L7: Gross Margin | M7: =M5-M6 -> 1418571
C8: Receivables | D8: 32375 | E8: 35525 | K8: Expenses
C9: Inventories | D9: 131250 | E9: 143937 | L9: Selling | M9: 439512
C10: Total Current Assets | D10: =SUM(D7:D9) -> 189192 | E10: =SUM(E7:E9) -> 222470 | L10: General & Administrative Variable | M10: 82514
B11: Fixed Assets | L11: General & Administrative Fixed | M11: 572776
C12: PP&E | D12: 395785 | E12: 470185 | L12: Depreciation | M12: 87221
C13: Less Depreciation | D13: 120221 | E13: 207442 | L13: Total Expenses | M13: =SUM(M9:M12) -> 1182023
C14: Total Fixed Assets | D14: =D12-D13 -> 275564 | E14: =E12-E13 -> 262743 | K14: EBIT | M14: =M7-M13 -> 236548
L15: Net Interest Expense | M15: 7535
B16: Total Assets | D16: =D10+D14 -> 464756 | E16: =E10+E14 -> 485213 | K16: Taxable Income | M16: =M14-M15 -> 229013
L17: Taxes | M17: 0
A18: Liabilities & Shareholder's Equity | K18: Net Income | M18: =M16-M17 -> 229013
B19: Current Liabilities | J19: Cash Flow Statement
C20: Accounts Payable | D20: 44625 | E20: 53286
C21: Accrued Liabilities | D21: 0 | E21: 0 | K21: Cash Provided (used) by Operations
C22: Bank Loan | D22: 201796 | E22: 159579 | K22: Net Income | M22: =M18 -> 229013
C23: Total Current Liabilities | D23: =SUM(D20:D22) -> 246421 | E23: =SUM(E20:E22) -> 212865 | K23: Plus Depreciation | M23: =M12 -> 87221
B24: Long Term Liabilities | D24: 0 | E24: 0 | K24: Change in Working Capital
C25: Total Liabilities | D25: =D23+D24 -> 246421 | E25: =E23+E24 -> 212865 | L25: Decrease (increase) in Receivables | M25: =D8-E8 -> -3150
L26: Decrease (increase) in Inventory | M26: =D9-E9 -> -12687
B27: Shareholder's Equity | L27: Increase (decrease) in Accts. Payable | M27: =E20-D20 -> 8661
C28: Member's Equity | D28: 150000 | E28: 150000 | L28: Increase (decrease) in Accrued Liabilities | M28: =E21-D21 -> 0
C29: Retained Earnings | D29: 68335 | E29: 122348 | L29: Cash Provided (used) by Operations | M29: =M22+M23+M25+M26+M27+M28 -> 309058
C30: Total Shareholder's Equity | D30: =SUM(D28:D29) -> 218335 | E30: =SUM(E28:E29) -> 272348 | K30: Cash Provided (used) by Investments
K31: Additions to PP&E | M31: =D12-E12 -> -74400
